<?xml version="1.0" ?>
<!-- =================================================================================== -->
<!-- |    This document was autogenerated by xacro from ../urdf/kr10r1100sixx.xacro    | -->
<!-- |    EDITING THIS FILE BY HAND IS NOT RECOMMENDED                                 | -->
<!-- =================================================================================== -->
<robot name="kuka_kr10r1100sixx" xmlns:xacro="http://wiki.ros.org/xacro">
  <!-- ROS control plugin -->
  <gazebo>
    <plugin filename="libgazebo_ros_control.so" name="gazebo_ros_control">
      <!--        <robotNamespace>/kr10r1100sixx</robotNamespace> -->
      <robotSimType>gazebo_ros_control/DefaultRobotHWSim</robotSimType>
    </plugin>
  </gazebo>
  <link name="base_link">
    <visual>
      <origin rpy="0.000000 0.000000 0.000000" xyz="0.000000 0.000000 0.000000"/>
      <geometry>
        <mesh filename="package://kuka_kr10r1100sixx_support/meshes/visual/base_link.dae"/>
      </geometry>
      <material name="">
        <color rgba="0 1 0 1"/>
      </material>
    </visual>
    <collision>
      <origin rpy="0.000000 0.000000 0.000000" xyz="0.000000 0.000000 0.000000"/>
      <geometry>
        <mesh filename="/opt/tra/path_finding/models/kuka_six/base_link.stl"/>
      </geometry>
    </collision>
    <inertial>
      <mass value="20.000000"/>
      <inertia ixx="0.000000" ixy="0.000000" ixz="0.000000" iyy="0.000000" iyz="0.000000" izz="0.000000"/>
    </inertial>
  </link>
  <link name="link_1">
    <visual>
      <origin rpy="0.000000 0.000000 0.000000" xyz="0.000000 0.000000 0.000000"/>
      <geometry>
        <mesh filename="package://kuka_kr10r1100sixx_support/meshes/visual/link_1.dae"/>
      </geometry>
      <material name="">
        <color rgba="0 1 0 1"/>
      </material>
    </visual>
    <collision>
      <origin rpy="0.000000 0.000000 0.000000" xyz="0.000000 0.000000 0.000000"/>
      <geometry>
        <mesh filename="/opt/tra/path_finding/models/kuka_six/link_1.stl"/>
      </geometry>
    </collision>
    <inertial>
      <mass value="10.470000"/>
      <inertia ixx="0.000000" ixy="0.000000" ixz="0.000000" iyy="0.000000" iyz="0.000000" izz="0.000000"/>
    </inertial>
  </link>
  <link name="link_2">
    <visual>
      <origin rpy="0.000000 0.000000 0.000000" xyz="0.000000 0.000000 0.000000"/>
      <geometry>
        <mesh filename="package://kuka_kr10r1100sixx_support/meshes/visual/link_2.dae"/>
      </geometry>
      <material name="">
        <color rgba="0 1 0 1"/>
      </material>
    </visual>
    <collision>
      <origin rpy="0.000000 0.000000 0.000000" xyz="0.000000 0.000000 0.000000"/>
      <geometry>
        <mesh filename="/opt/tra/path_finding/models/kuka_six/link_2.stl"/>
      </geometry>
    </collision>
    <inertial>
      <mass value="12.770000"/>
      <inertia ixx="0.000000" ixy="0.000000" ixz="0.000000" iyy="0.000000" iyz="0.000000" izz="0.000000"/>
    </inertial>
  </link>
  <link name="link_3">
    <visual>
      <origin rpy="0.000000 0.000000 0.000000" xyz="0.000000 0.000000 0.000000"/>
      <geometry>
        <mesh filename="package://kuka_kr10r1100sixx_support/meshes/visual/link_3.dae"/>
      </geometry>
      <material name="">
        <color rgba="0 1 0 1"/>
      </material>
    </visual>
    <collision>
      <origin rpy="0.000000 0.000000 0.000000" xyz="0.000000 0.000000 0.000000"/>
      <geometry>
        <mesh filename="/opt/tra/path_finding/models/kuka_six/link_3.stl"/>
      </geometry>
    </collision>
    <inertial>
      <mass value="6.020000"/>
      <inertia ixx="0.060000" ixy="0.000000" ixz="0.000000" iyy="0.008000" iyz="0.000000" izz="0.060000"/>
    </inertial>
  </link>
  <link name="link_4">
    <visual>
      <origin rpy="0.000000 0.000000 0.000000" xyz="0.000000 0.000000 0.000000"/>
      <geometry>
        <mesh filename="package://kuka_kr10r1100sixx_support/meshes/visual/link_4.dae"/>
      </geometry>
      <material name="">
        <color rgba="0 1 0 1"/>
      </material>
    </visual>
    <collision>
      <origin rpy="0.000000 0.000000 0.000000" xyz="0.000000 0.000000 0.000000"/>
      <geometry>
        <mesh filename="/opt/tra/path_finding/models/kuka_six/link_4.stl"/>
      </geometry>
    </collision>
    <inertial>
      <mass value="4.000000"/>
      <inertia ixx="0.482085" ixy="0.000000" ixz="0.000000" iyy="0.480795" iyz="0.000000" izz="0.012860"/>
    </inertial>
  </link>
  <link name="link_5">
    <visual>
      <origin rpy="0.000000 0.000000 0.000000" xyz="0.000000 0.000000 0.000000"/>
      <geometry>
        <mesh filename="package://kuka_kr10r1100sixx_support/meshes/visual/link_5.dae"/>
      </geometry>
      <material name="">
        <color rgba="0 1 0 1"/>
      </material>
    </visual>
    <collision>
      <origin rpy="0.000000 0.000000 0.000000" xyz="0.000000 0.000000 0.000000"/>
      <geometry>
        <mesh filename="/opt/tra/path_finding/models/kuka_six/link_5.stl"/>
      </geometry>
    </collision>
    <inertial>
      <mass value="1.550000"/>
      <inertia ixx="0.002658" ixy="0.000000" ixz="0.000000" iyy="0.002537" iyz="0.000000" izz="0.001224"/>
    </inertial>
  </link>
  <link name="link_6">
    <visual>
      <origin rpy="0.000000 0.000000 0.000000" xyz="0.000000 0.000000 0.000000"/>
      <geometry>
        <mesh filename="package://kuka_kr10r1100sixx_support/meshes/visual/link_6.dae"/>
      </geometry>
      <material name="">
        <color rgba="0 1 0 1"/>
      </material>
    </visual>
    <collision>
      <origin rpy="0.000000 0.000000 0.000000" xyz="0.000000 0.000000 0.000000"/>
      <geometry>
        <mesh filename="/opt/tra/path_finding/models/kuka_six/link_6.stl"/>
      </geometry>
    </collision>
    <inertial>
      <mass value="0.190000"/>
      <inertia ixx="0.000885" ixy="0.000000" ixz="0.000000" iyy="0.000885" iyz="0.000000" izz="0.000043"/>
    </inertial>
  </link>
  <!-- This frame corresponds to the $FLANGE coordinate system in controllers -->
  <link name="tool0"/>
  <joint name="joint_1" type="revolute">
    <origin rpy="0 0.000000 0" xyz="0.000000 0.000000 0.400000"/>
    <parent link="base_link"/>
    <child link="link_1"/>
    <axis xyz="0 0 -1"/>
    <limit effort="372.000000" lower="-2.967060" upper="2.967060" velocity="5.235988"/>
    <dynamics damping="0.0" friction="0.1"/>
  </joint>
  <joint name="joint_2" type="revolute">
    <origin rpy="0 0.000000 0" xyz="0.025000 0.000000 0.000000"/>
    <parent link="link_1"/>
    <child link="link_2"/>
    <axis xyz="0 1 0"/>
    <limit effort="300.000000" lower="-3.316126" upper="0.785398" velocity="3.926991"/>
    <dynamics damping="0.0" friction="0.1"/>
  </joint>
  <joint name="joint_3" type="revolute">
    <origin rpy="0 0.000000 0" xyz="0.560000 0.000000 0.000000"/>
    <parent link="link_2"/>
    <child link="link_3"/>
    <axis xyz="0 1 0"/>
    <limit effort="161.000000" lower="-2.094395" upper="2.722714" velocity="3.926991"/>
    <dynamics damping="0.0" friction="0.1"/>
  </joint>
  <joint name="joint_4" type="revolute">
    <origin rpy="0 0.000000 0" xyz="0.000000 0.000000 0.035000"/>
    <parent link="link_3"/>
    <child link="link_4"/>
    <axis xyz="-1 0 0"/>
    <limit effort="41.000000" lower="-3.228859" upper="3.228859" velocity="6.649704"/>
    <dynamics damping="0.0" friction="0.1"/>
  </joint>
  <joint name="joint_5" type="revolute">
    <origin rpy="0 0.000000 0" xyz="0.515000 0.000000 0.000000"/>
    <parent link="link_4"/>
    <child link="link_5"/>
    <axis xyz="0 1 0"/>
    <limit effort="41.000000" lower="-2.094395" upper="2.094395" velocity="5.427974"/>
    <dynamics damping="0.0" friction="0.1"/>
  </joint>
  <joint name="joint_6" type="revolute">
    <origin rpy="0 0.000000 0" xyz="0.080000 0.000000 0.000000"/>
    <parent link="link_5"/>
    <child link="link_6"/>
    <axis xyz="-1 0 0"/>
    <limit effort="28.000000" lower="-6.108652" upper="6.108652" velocity="8.587020"/>
    <dynamics damping="0.0" friction="0.1"/>
  </joint>
  <joint name="joint_6-tool0" type="fixed">
    <parent link="link_6"/>
    <child link="tool0"/>
    <origin rpy="0 1.570796 0" xyz="0 0 0"/>
  </joint>
  <!-- TRANSMISSION -->
  <transmission name="tran_1">
    <type>transmission_interface/SimpleTransmission</type>
    <joint name="joint_1">
      <hardwareInterface>hardware_interface/PositionJointInterface</hardwareInterface>
    </joint>
    <actuator name="motor_1">
      <hardwareInterface>hardware_interface/PositionJointInterface</hardwareInterface>
      <mechanicalReduction>1</mechanicalReduction>
    </actuator>
  </transmission>
  <transmission name="tran_2">
    <type>transmission_interface/SimpleTransmission</type>
    <joint name="joint_2">
      <hardwareInterface>hardware_interface/PositionJointInterface</hardwareInterface>
    </joint>
    <actuator name="motor_2">
      <hardwareInterface>hardware_interface/PositionJointInterface</hardwareInterface>
      <mechanicalReduction>1</mechanicalReduction>
    </actuator>
  </transmission>
  <transmission name="tran_3">
    <type>transmission_interface/SimpleTransmission</type>
    <joint name="joint_3">
      <hardwareInterface>hardware_interface/PositionJointInterface</hardwareInterface>
    </joint>
    <actuator name="motor_3">
      <hardwareInterface>hardware_interface/PositionJointInterface</hardwareInterface>
      <mechanicalReduction>1</mechanicalReduction>
    </actuator>
  </transmission>
  <transmission name="tran_4">
    <type>transmission_interface/SimpleTransmission</type>
    <joint name="joint_4">
      <hardwareInterface>hardware_interface/PositionJointInterface</hardwareInterface>
    </joint>
    <actuator name="motor_4">
      <hardwareInterface>hardware_interface/PositionJointInterface</hardwareInterface>
      <mechanicalReduction>1</mechanicalReduction>
    </actuator>
  </transmission>
  <transmission name="tran_5">
    <type>transmission_interface/SimpleTransmission</type>
    <joint name="joint_5">
      <hardwareInterface>hardware_interface/PositionJointInterface</hardwareInterface>
    </joint>
    <actuator name="motor_5">
      <hardwareInterface>hardware_interface/PositionJointInterface</hardwareInterface>
      <mechanicalReduction>1</mechanicalReduction>
    </actuator>
  </transmission>
  <transmission name="tran_6">
    <type>transmission_interface/SimpleTransmission</type>
    <joint name="joint_6">
      <hardwareInterface>hardware_interface/PositionJointInterface</hardwareInterface>
    </joint>
    <actuator name="motor_6">
      <hardwareInterface>hardware_interface/PositionJointInterface</hardwareInterface>
      <mechanicalReduction>1</mechanicalReduction>
    </actuator>
  </transmission>
  <gazebo reference="base_link">
    <turnGravityOff>false</turnGravityOff>
    <selfCollide>true</selfCollide>
  </gazebo>
  <gazebo reference="link_1">
    <turnGravityOff>false</turnGravityOff>
    <selfCollide>true</selfCollide>
  </gazebo>
  <gazebo reference="link_2">
    <turnGravityOff>false</turnGravityOff>
    <selfCollide>true</selfCollide>
  </gazebo>
  <gazebo reference="link_3">
    <turnGravityOff>false</turnGravityOff>
    <selfCollide>true</selfCollide>
  </gazebo>
  <gazebo reference="link_4">
    <turnGravityOff>false</turnGravityOff>
    <selfCollide>true</selfCollide>
  </gazebo>
  <gazebo reference="link_5">
    <turnGravityOff>false</turnGravityOff>
    <selfCollide>true</selfCollide>
  </gazebo>
  <gazebo reference="link_6">
    <turnGravityOff>false</turnGravityOff>
    <selfCollide>true</selfCollide>
  </gazebo>
  <link name="world"/>
  <joint name="world_joint" type="fixed">
    <parent link="world"/>
    <child link="base_link"/>
    <origin rpy="0.0 0.0 0.0" xyz="0.0 0.0 0.0"/>
  </joint>
</robot>
